work/Exchange/output.txt
T,1,B,Apples,3,4,1,258.48
X,3
X,5
T,2,B,Apples,9,10,4,264.60
X,6
T,3,B,Apples,9,11,58,264.60
T,4,B,Apples,2,11,4,275.40
T,5,B,Apples,7,11,37,278.20
X,8
T,6,B,Apples,12,14,61,264.48
T,7,B,Apples,13,14,6,296.72
